Workbook

Sheet 1. INPUTS
A1: ASML HOLDING N.V. | VALUATION MODEL INPUTS
A2: All figures in €m unless stated
A4: Input Parameter | B4: Value | C4: Units / Type | D4: Source / Justification
A5: A. MARKET DATA (as of 31 March 2026)
A6: Share Price (Current) | B6: 1150 | C6: EUR / share | D6: Euronext Amsterdam (ASML.AS) closing price, end-March 2026. 52W high €1,313 (25-Feb-26); stock up ~69% from Apr-2025 level. Source: Yahoo Finance / Bloomberg, Mar-2026
A7: Shares Outstanding | B7: 383 | C7: million shares | D7: Diluted shares ~383m as of Mar-2026. FY2025 weighted avg diluted 388.9m. ASML repurchased €5.95bn shares in 2025 (avg price ~€800). Source: ASML 6-K Q4 2025, Jan 28 2026
A8: Market Capitalisation | B8: =B6*B7/1000 -> 440.45 | C8: €bn | D8: Calculated: Share Price × Shares Outstanding
A9: 52-Week High | B9: 1313 | C9: EUR / share | D9: Euronext ATH: €1,312.80 on 25-Feb-2026 (post FY2025 record results). Source:MacroTrends, Mar-2026
A10: 52-Week Low | B10: 542 | C10: EUR / share | D10: 52-week low (Apr-2025, post Q4 2024 weak order intake). Source: Investing.com, Mar-2026
A11: Enterprise Value (estimated) | B11: 429000 | C11: €m | D11: Market Cap ~€440bn less net cash ~€11bn = EV ~€429bn. Source: Derived from market data + ASML AR 2025 balance sheet
A12: B. REVENUE ACTUALS (A = Actual | E = Estimated)
A13: FY2021 Revenue [A] | B13: 18611 | C13: A - Actual | D13: ASML Annual Report 2021, Consolidated P&L, p.140
A14: FY2022 Revenue [A] | B14: 21173 | C14: A - Actual | D14: ASML Annual Report 2022, Consolidated P&L, p.145
A15: FY2023 Revenue [A] | B15: 27559 | C15: A - Actual | D15: ASML Annual Report 2023, Consolidated P&L, p.152
A16: FY2024 Revenue [A] | B16: 28261 | C16: A - Actual | D16: ASML Annual Report 2024, Consolidated P&L, p.158
A17: FY2025 Revenue [A] | B17: 32667 | C17: A - Actual | D17: ASML FY2025 actual: Total net sales €32,667m (+15.6% YoY). Gross margin 52.8%. Source: ASML 6-K Q4/FY2025, 28-Jan-2026 (SEC EDGAR)
A18: C. REVENUE GROWTH ASSUMPTIONS [Assumed – Forward Projections]
A19: FY2026 Revenue Growth Rate | B19: 0.12 | C19: Assumed | D19: High-NA ramp + AI-driven TSMC/Samsung orders; consensus ~10–14%
A20: FY2027 Revenue Growth Rate | B20: 0.1 | C20: Assumed | D20: High-NA EUV ramp acceleration; TSMC N2 capacity build
A21: FY2028 Revenue Growth Rate | B21: 0.08 | C21: Assumed | D21: High-NA EUV adoption and growth in installed base service revenues
A22: FY2029 Revenue Growth Rate | B22: 0.06 | C22: Assumed | D22: Moderation post peak ramp; assumes no new export shocks
A23: FY2030 Revenue Growth Rate | B23: 0.05 | C23: Assumed | D23: Conservative maturing cycle; aligns to ASML 2030 Scenario
A24: D. MARGIN ASSUMPTIONS [Assumed]
A25: EBIT Margin FY2026 | B25: 0.33 | C25: Assumed | D25: Consistent with FY2023 level; High-NA dilution offset by IBM growth
A26: EBIT Margin FY2027 | B26: 0.33 | C26: Assumed | D26: High-NA margins improving; Operating leverage on fixed cost base
A27: EBIT Margin FY2028 | B27: 0.34 | C27: Assumed | D27: High-NA margins maturing toward 55% GM; ASML 2030 scenario target
A28: EBIT Margin FY2029 | B28: 0.34 | C28: Assumed | D28: Stable margin profile; assumes no material cost headwinds
A29: EBIT Margin FY2030 | B29: 0.35 | C29: Assumed | D29: Upside scenario: High-NA at full margin; IBM at scale
A30: Effective Tax Rate | B30: 0.145 | C30: Assumed | D30: ASML AR 2024 effective tax rate ~14.5%; Dutch innovation box regime
A31: D&A as % of Revenue | B31: 0.03 | C31: Assumed | D31: Updated: FY2025 actual D&A €1,026m / revenue €32,667m = 3.1%. Prior model used 2% (understated). Source: ASML 6-K Q4 2025 cash flow statement
A32: Capex as % of Revenue | B32: 0.05 | C32: Assumed | D32: ASML AR 2024 capex €1.4bn / €28.3bn rev = ~5%; guided stable
A33: Change in WC (% Rev) | B33: 0.005 | C33: Assumed | D33: Simplified: minimal WC change assumption; conservative
A34: E. DCF & WACC INPUTS [Assumed]
A35: WACC | B35: 0.09 | C35: Assumed | D35: Derived from CAPM; see CAPM sheet. Cost of debt ~3.5%, D/E ~5%
A36: Terminal Growth Rate | B36: 0.03 | C36: Assumed | D36: Conservative: ~nominal GDP + inflation; below revenue CAGR
A37: Net Debt (FY2025) | B37: -11000 | C37: A - Actual | D37: FY2025 net cash position: Cash + ST investments €13,322m less financial debt ~€2,300m = net cash ~€11,000m (stored as negative = net cash added back in equity bridge). Source: ASML 6-K Q4 2025 balance sheet, Jan 2026
A38: Price Target (12-Month) | B38: =('3. DCF VALUATION'!B35+'4. COMP VALUATION'!H21)/2 -> 577.68137 | C38: Analyst Est. | D38: Model-derived: Average of DCF intrinsic value and Comparable Companies average implied price. See sheets 3 and 4 for details.
A40: COLOUR KEY
A41: ■ SAMPLE | B41: Blue text on blue background = Hardcoded input
A42: ■ SAMPLE | B42: Green text on green background = Calculated formula (cross-sheet link)
...

Sheet 2. HISTORICAL
A1: ASML HOLDING N.V. | HISTORICAL FINANCIAL PERFORMANCE (FY2021–FY2025A)
A2: All figures in €m | A = Actual from ASML Annual Reports & SEC 6-K filings
A4: Metric | B4: FY2021 [A] | C4: FY2022 [A] | D4: FY2023 [A] | E4: FY2024 [A] | F4: FY2025 [A]
A5: I. INCOME STATEMENT SUMMARY
A6: Revenue | B6: 18611 | C6: 21173 | D6: 27559 | E6: 28261 | F6: 32667
A7: YoY Growth | B7: - | C7: =(C6-B6)/B6 -> 0.13766052 | D7: =(D6-C6)/C6 -> 0.30161054 | E7: =(E6-D6)/D6 -> 0.025472622 | F7: =(F6-E6)/E6 -> 0.1559039
A8: Gross Profit | B8: 9813 | C8: 10558 | D8: 14128 | E8: 14426 | F8: 17258
A9: Gross Margin | B9: =B8/B6 -> 0.52726882 | C9: =C8/C6 -> 0.49865395 | D9: =D8/D6 -> 0.5126456 | E9: =E8/E6 -> 0.51045611 | F9: =F8/F6 -> 0.52830073
A10: EBIT | B10: 5731 | C10: 5952 | D10: 9015 | E10: 9023 | F10: 11301
A11: EBIT Margin | B11: =B10/B6 -> 0.30793617 | C11: =C10/C6 -> 0.28111274 | D11: =D10/D6 -> 0.32711637 | E11: =E10/E6 -> 0.31927391 | F11: =F10/F6 -> 0.34594545
A12: Net Income | B12: 5882 | C12: 5624 | D12: 7837 | E12: 7572 | F12: 9609
A13: Net Margin | B13: =B12/B6 -> 0.31604965 | C13: =C12/C6 -> 0.26562131 | D13: =D12/D6 -> 0.28437171 | E13: =E12/E6 -> 0.26793107 | F13: =F12/F6 -> 0.29415006
A14: EPS (diluted, €) | B14: 13.49 | C14: 13.61 | D14: 21 | E14: 19.24 | F14: 24.71
A16: II. SIMPLIFIED CASH FLOW METRICS
A17: D&A (approx.) | B17: 356 | C17: 400 | D17: 498 | E17: 919 | F17: 1026
A18: Capital Expenditure | B18: 740 | C18: 893 | D18: 1166 | E18: 2083 | F18: 1631
A19: Free Cash Flow (approx) | B19: 4500 | C19: 5200 | D19: 6900 | E19: 9083 | F19: 11028
A20: FCF Margin | B20: =B19/B6 -> 0.24179249 | C20: =C19/C6 -> 0.24559581 | D20: =D19/D6 -> 0.25037193 | E20: =E19/E6 -> 0.32139698 | F20: =F19/F6 -> 0.33758839
A21: FCF / Net Income | B21: =B19/B12 -> 0.7650459 | C21: =C19/C12 -> 0.92460882 | D21: =D19/D12 -> 0.88043894 | E21: =E19/E12 -> 1.199551 | F21: =F19/F12 -> 1.1476741
A22: Order Intake (€m) | B22: 26000 | C22: 40400 | D22: 39400 | E22: 18900 | F22: 27200
A23: Order Backlog (€m) | B23: 33000 | C23: 40400 | D23: 39400 | E23: 36000 | F23: 38800
A25: III. MARKET METRICS & IMPLIED MULTIPLES
A26: AUDIT NOTE: FY2024 data corrected vs original model (EBIT +€540m, NI +€232m, D&A +€357m, Capex +€678m). FY2025 updated from Estimate to Actual (Revenue +€867m, NI +€639m, EPS +€1.91, D&A +€390m). Source: ASML 6-K Q4/FY2025 filed 28-Jan-2026 (SEC EDGAR).
A27: P/E (trailing, ×) | B27: 48.2x | C27: 38.2x | D27: 28.6 | E27: 34.3x | F27: 29.8x
A28: EV/EBIT (×) | B28: 45.9 | C28: 44.1 | D28: 29.1 | E28: 31 | F28: 25

Sheet 3. DCF VALUATION
A1: ASML HOLDING N.V. | DISCOUNTED CASH FLOW VALUATION
A2: 5-Year Forecast (FY2026–FY2030) | All figures in €m | Valued as of 31 March 2026 | Blue = Input | Black = Formula | Green = Cross-sheet Link
A4: Line Item | B4: FY2025E | C4: FY2026E | D4: FY2027E | E4: FY2028E | F4: FY2029E | G4: FY2030E
A5: I. REVENUE BUILD
A6: Revenue (€m) | B6: ='1. INPUTS'!B17 -> 32667 | C6: =B6*(1+'1. INPUTS'!B19) -> 36587.04 | D6: =C6*(1+'1. INPUTS'!B20) -> 40245.744 | E6: =D6*(1+'1. INPUTS'!B21) -> 43465.404 | F6: =E6*(1+'1. INPUTS'!B22) -> 46073.328 | G6: =F6*(1+'1. INPUTS'!B23) -> 48376.994
A7: YoY Growth Rate | B7: ='1. INPUTS'!B19 -> 0.12 | C7: ='1. INPUTS'!B20 -> 0.1 | D7: ='1. INPUTS'!B21 -> 0.08 | E7: ='1. INPUTS'!B22 -> 0.06 | F7: ='1. INPUTS'!B23 -> 0.05
A9: II. EBIT → NOPAT → FREE CASH FLOW (Simplified)
A10: EBIT Margin (%) | B10: ='2. HISTORICAL'!F11 -> 0.34594545 | C10: ='1. INPUTS'!B25 -> 0.33 | D10: ='1. INPUTS'!B26 -> 0.33 | E10: ='1. INPUTS'!B27 -> 0.34 | F10: ='1. INPUTS'!B28 -> 0.34 | G10: ='1. INPUTS'!B29 -> 0.35
A11: EBIT (€m) | B11: =B6*B10 -> 11301 | C11: =C6*C10 -> 12073.723 | D11: =D6*D10 -> 13281.096 | E11: =E6*E10 -> 14778.237 | F11: =F6*F10 -> 15664.931 | G11: =G6*G10 -> 16931.948
A12: Tax (@ effective rate) | B12: =B11*'1. INPUTS'!B30 -> 1638.645 | C12: =C11*'1. INPUTS'!B30 -> 1750.6899 | D12: =D11*'1. INPUTS'!B30 -> 1925.7589 | E12: =E11*'1. INPUTS'!B30 -> 2142.8444 | F12: =F11*'1. INPUTS'!B30 -> 2271.4151 | G12: =G11*'1. INPUTS'!B30 -> 2455.1325
A13: NOPAT (Net Op. Profit After Tax) | B13: =B11-B12 -> 9662.355 | C13: =C11-C12 -> 10323.033 | D13: =D11-D12 -> 11355.337 | E13: =E11-E12 -> 12635.393 | F13: =F11-F12 -> 13393.516 | G13: =G11-G12 -> 14476.815
A15: (+) D&A (% of Revenue) | B15: =B6*'1. INPUTS'!B31 -> 980.01 | C15: =C6*'1. INPUTS'!B31 -> 1097.6112 | D15: =D6*'1. INPUTS'!B31 -> 1207.3723 | E15: =E6*'1. INPUTS'!B31 -> 1303.9621 | F15: =F6*'1. INPUTS'!B31 -> 1382.1998 | G15: =G6*'1. INPUTS'!B31 -> 1451.3098
A16: (–) Capex (% of Revenue) | B16: =B6*'1. INPUTS'!B32 -> 1633.35 | C16: =C6*'1. INPUTS'!B32 -> 1829.352 | D16: =D6*'1. INPUTS'!B32 -> 2012.2872 | E16: =E6*'1. INPUTS'!B32 -> 2173.2702 | F16: =F6*'1. INPUTS'!B32 -> 2303.6664 | G16: =G6*'1. INPUTS'!B32 -> 2418.8497
A17: (–) Δ Working Capital (% of Rev) | B17: =B6*'1. INPUTS'!B33 -> 163.335 | C17: =C6*'1. INPUTS'!B33 -> 182.9352 | D17: =D6*'1. INPUTS'!B33 -> 201.22872 | E17: =E6*'1. INPUTS'!B33 -> 217.32702 | F17: =F6*'1. INPUTS'!B33 -> 230.36664 | G17: =G6*'1. INPUTS'!B33 -> 241.88497
A18: FREE CASH FLOW TO FIRM (FCFF) | B18: =B13+B15-B16-B17 -> 8845.68 | C18: =C13+C15-C16-C17 -> 9408.3573 | D18: =D13+D15-D16-D17 -> 10349.193 | E18: =E13+E15-E16-E17 -> 11548.758 | F18: =F13+F15-F16-F17 -> 12241.683 | G18: =G13+G15-G16-G17 -> 13267.391
A19: FCF Margin (%) | B19: =B18/B6 -> 0.27078336 | C19: =C18/C6 -> 0.25715 | D19: =D18/D6 -> 0.25715 | E19: =E18/E6 -> 0.2657 | F19: =F18/F6 -> 0.2657 | G19: =G18/G6 -> 0.27425
A21: III. DISCOUNTING & TERMINAL VALUE
A22: Discount Period (years) | B22: 0 | C22: 0.5 | D22: 1.5 | E22: 2.5 | F22: 3.5 | G22: 4.5
A23: Discount Factor [1/(1+WACC)^t] | B23: =1/(1+'1. INPUTS'!B35)^B22 -> 1 | C23: =1/(1+'1. INPUTS'!B35)^C22 -> 0.95782629 | D23: =1/(1+'1. INPUTS'!B35)^D22 -> 0.87873971 | E23: =1/(1+'1. INPUTS'!B35)^E22 -> 0.80618322 | F23: =1/(1+'1. INPUTS'!B35)^F22 -> 0.73961763 | G23: =1/(1+'1. INPUTS'!B35)^G22 -> 0.67854829
A24: PV of FCFF (discounted) | B24: - | C24: =C18*C23 -> 9011.572 | D24: =D18*D23 -> 9094.2469 | E24: =E18*E23 -> 9310.4147 | F24: =F18*F23 -> 9054.1648 | G24: =G18*G23 -> 9002.5652
A25: Sum of PV FCFFs (FY2026–FY2030) | B25: =SUM(C24:G24) -> 45472.964
A27: Terminal Value [Gordon Growth: FCF₂₀₃₀ × (1+g) / (WACC–g)] | B27: =G18*(1+'1. INPUTS'!B36)/('1. INPUTS'!B35-'1. INPUTS'!B36) -> 227756.87
A28: PV of Terminal Value | B28: =B27*G23 -> 154544.04
A30: IV. EQUITY VALUE BRIDGE → INTRINSIC VALUE PER SHARE
A31: Enterprise Value (Sum PV FCFF + PV Terminal Value) | B31: =B25+B28 -> 200017
A32: (–) Net Debt / (+) Net Cash [from Inputs] | B32: =-'1. INPUTS'!B37 -> 11000
A33: Equity Value | B33: =B31+B32 -> 211017
A34: Shares Outstanding (m) [from Inputs] | B34: ='1. INPUTS'!B7 -> 383
A35: INTRINSIC VALUE PER SHARE (€) | B35: =B33/B34 -> 550.95822
A36: Current Share Price (€) [from Inputs] | B36: ='1. INPUTS'!B6 -> 1150
A37: Upside / (Downside) (%) | B37: =(B35-B36)/B36 -> -0.52090589
A39: AUDIT NOTE (Mar-2026 update): FY2025 base reflects actual revenue €32,667m (+15.6% vs prior FY2025E of €31,800m). D&A assumption updated from 2.0% to 3.0% of revenue based on FY2025 actual D&A of €1,026m (3.14% of revenue). Net cash updated to €11,000m (FY2025 cash €13,322m less debt ~€2,300m). Discount periods corrected to mid-year convention from 31-Mar-2026 (FY2026=0.5y ... FY2030=4.5y). WACC: 10.0% (CAPM-derived: Rf 2.8% + Beta 1.35 × ERP 5.5% = 10.2% Ke; net debt ~zero → WACC≈Ke less small debt benefit).

Sheet 4. COMP VALUATION
A1: ASML HOLDING N.V. | COMPARATIVE (TRADING COMPS) VALUATION
A2: NTM = Next Twelve Months (FY2026E) consensus | Source:ASML Annual Reports, SEC 6-K filings, and consensus-based estimates derived from publicly available financial data platforms March 2026 | Figures in EUR unless noted
A4: I. SEMICONDUCTOR EQUIPMENT PEER UNIVERSE
A5: Company | B5: Ticker | C5: Mkt Cap (€/$ bn) | D5: NTM P/E (×) | E5: EV/ EBITDA (×) | F5: EV/ Sales (×) | G5: Rev Growth | H5: Gross Margin
A6: ASML Holding | B6: ASML NA | C6: 440 | D6: 40 | E6: 31 | F6: 12 | G6: 0.12 | H6: 0.528
A7: Applied Materials | B7: AMAT US | C7: 120 | D7: 20 | E7: 15 | F7: 5 | G7: 0.08 | H7: 0.47
A8: Lam Research | B8: LRCX US | C8: 80 | D8: 22 | E8: 16 | F8: 6 | G8: 0.09 | H8: 0.48
A9: KLA Corporation | B9: KLAC US | C9: 70 | D9: 25 | E9: 18 | F9: 8 | G9: 0.07 | H9: 0.6
A10: Tokyo Electron | B10: 8035 JP | C10: 85 | D10: 28 | E10: 20 | F10: 7 | G10: 0.1 | H10: 0.46
A12: Peer Average (excl. ASML) | B12: - | C12: =AVERAGE(C7:C10) -> 88.75 | D12: =AVERAGE(D7:D10) -> 23.75 | E12: =AVERAGE(E7:E10) -> 17.25 | F12: =AVERAGE(F7:F10) -> 6.5 | G12: =AVERAGE(G7:G10) -> 0.085 | H12: =AVERAGE(H7:H10) -> 0.5025
A13: ASML Premium / (Discount) | B13: - | C13: - | D13: =(D6-D12)/D12 -> 0.68421053 | E13: =(E6-E12)/E12 -> 0.79710145 | F13: =(F6-F12)/F12 -> 0.84615385 | G13: - | H13: -
A15: II. IMPLIED VALUATION (Applying Peer Multiples to ASML)
A16: Methodology: Apply peer average multiple to ASML NTM metric → derive implied EV → subtract net debt → divide by shares outstanding. Results cross-validate DCF.
A17: Approach | B17: Multiple Used | C17: Peer Avg Multiple | D17: ASML Metric | E17: Implied EV (€m) | F17: – Net Debt (€m) | G17: Equity Val (€m) | H17: Implied Price (€)
A18: P/E Implied Price | B18: NTM P/E | C18: =D12 -> 23.75 | D18: ='2. HISTORICAL'!F14 -> 24.71 | E18: N/A — P/E method does not use EV bridge | F18: N/A — P/E method does not use EV bridge | G18: N/A — P/E method does not use EV bridge | H18: =C18*D18 -> 586.8625
A19: EV/EBITDA Implied Price | B19: NTM EV/EBITDA | C19: =E12 -> 17.25 | D19: ='3. DCF VALUATION'!C11+'3. DCF VALUATION'!C15 -> 13171.334 | E19: =C19*D19 -> 227205.52 | F19: ='1. INPUTS'!B37 -> -11000 | G19: =E19-'1. INPUTS'!B37 -> 238205.52 | H19: =G19/'1. INPUTS'!B7 -> 621.94652
A21: Average Implied Price (Comps, €) | H21: =AVERAGE(H18:H19) -> 604.40451
A22: Current Share Price (€) | H22: ='1. INPUTS'!B6 -> 1150
A23: Upside / (Downside) (%) | H23: =(H21-H22)/H22 -> -0.47443086
A25: AUDIT NOTE (Mar-2026 update): Peer multiples aligned to March 2026 market conditions using consensus-based estimates derived from publicly available financial data platforms. ASML P/E ~40x vs peer avg ~24x (+67% premium). P/E methodology: Price = EPS × Peer P/E (no EV bridge). EV/EBITDA methodology: Implied EV derived from peer multiple, then adjusted for net cash and divided by shares outstanding. Net debt sign corrected: ASML net cash €11,000m is added to implied EV. NTM EBITDA proxied using FY2026E forecast consistent with consensus growth assumptions. All per-share outputs in EUR (no ×1000 applied). Source: ASML Annual Reports, SEC 6-K Q4 2025, and publicly available financial data platforms.

Sheet 5. CAPM
A1: ASML HOLDING N.V. | CAPM — REQUIRED RETURN ANALYSIS
A2: Capital Asset Pricing Model: E(Ri) = Rf + βi × [E(Rm) – Rf] | Blue = Input | Black = Formula
A4: Parameter | B4: Value | C4: Units | D4: Source / Justification
A5: I. CAPM INPUTS
A6: Risk-Free Rate (Rf) | B6: 0.028 | C6: % p.a. | D6: 10Y German Bund yield ~2.8% as of March 2026. Slightly higher than Apr-2025 (2.5%) reflecting ECB rate environment. Source:Source: Deutsche Bundesbank, Yahoo Finance, publicly available financial data platforms (Mar-2026)
A7: Equity Beta (β) | B7: 1.35 | C7: 5Y monthly | D7: Reflects WFE cyclicality + geopolitical risk premium. Damodaran sector beta: ~1.2–1.4
A8: Equity Risk Premium (ERP) | B8: 0.055 | C8: % p.a. | D8: Damodaran Implied ERP for Western Europe, January 2025 update. URL: pages.stern.nyu.edu/~adamodar
A9: Market Return E(Rm) | B9: =B6+B8 -> 0.083 | C9: % p.a. | D9: Formula: Rf + ERP; implied from CAPM inputs above
A11: II. CAPM OUTPUT — REQUIRED RETURN
A12: Required Return E(Ri) = Rf + β × ERP | B12: =B6+B7*B8 -> 0.10225 | C12: % p.a. | D12: Formula: 2.8% + (1.35 × 5.5%) = 10.225% ≈ 10.2%. Updated Rf = 2.8% (Mar-2026). This is the MINIMUM annual return required to compensate for ASML's systematic risk.
A14: III. ALPHA SIGNAL (DCF Implied Return vs Required Return)
A15: DCF Intrinsic Value (€/share) | B15: ='3. DCF VALUATION'!B35 -> 550.95822 | C15: €/share | D15: Cross-link from DCF sheet; Gordon-Growth DCF output
A16: Current Share Price (€/share) | B16: ='1. INPUTS'!B6 -> 1150 | C16: €/share | D16: Cross-link from Inputs sheet; €1,150/share Euronext closing price, March 2026. Source: Bloomberg / Yahoo Finance (ASML.AS), Mar-2026
A17: Implied Capital Gain (3-Year) | B17: =(B15/B16)^(1/3)-1 -> -0.21751934 | C17: % p.a. | D17: 3-year convergence formula: (DCF Intrinsic / Current Price)^(1/3) – 1. Assumes price gradually converges to intrinsic value over 3 years. Negative result → model implies stock is ABOVE intrinsic value → overvaluation signal.
A18: Dividend Yield (approx.) | B18: 0.009 | C18: % p.a. | D18: ASML FY2025 total dividend ~€10.80/share (4 × €2.70). Yield at €1,150 = 0.94%. Used 0.9% conservative estimate. Source: ASML investor relations / Digrin, Mar-2026
A19: Total Implied Return (3Y Ann. Capital Gain + Div Yield) | B19: =B17+B18 -> -0.20851934 | C19: % p.a. | D19: Total implied return = (annual capital gain from 3Y convergence) + dividend yield. When negative: This represents a valuation-based return proxy rather than a precise forecast. It indicates that the current market price embeds more optimistic assumptions than the model.
A20: Required Return (CAPM) | B20: =B12 -> 0.10225 | C20: % p.a. | D20: Cross-link from CAPM output above
A21: ALPHA (Implied – Required) | B21: =B19-B20 -> -0.31076934 | C21: % p.a. | D21: Negative alpha → current price EXCEEDS model intrinsic value → Negative alpha suggests the stock appears overvalued under the model’s base-case assumptions.
A23: IV. MARKET EFFICIENCY ASSESSMENT
A24: Market Efficiency Form | B24: Semi-Strong | C24: Degree | D24: ASML is a large-cap, high-analyst-coverage stock. Public info (earnings, guidance, export controls) rapidly reflected in price.
A25: Identified Pricing Anomaly? | B25: NO — Model-Implied OVERVALUATION | C25: Judgement | D25: Both DCF and Comps imply market price significantly exceeds model intrinsic value. The market IS pricing in more aggressive assumptions: High-NA ramp beyond model scope, AI-driven TSMC/Samsung CapEx optionality, and IBM segment compounding. This does NOT mean ASML is a bad business — it means the current price reflects optimistic scenario, not base-case conservative estimates.
A26: Behavioral Bias Identified | B26: Momentum + FOMO Bias | C26: Type | D26: Stock up 103% over the last 12 months (to Mar-2026). Momentum traders and AI-theme index flows driving premium valuations. FOMO (fear of missing out) as ASML becomes proxy for AI hardware supply chain investment.
A27: Analyst Consensus Bias | B27: Consensus targets above model | C27: Judgement | D27: Sell-side consensus price targets range €955–€1,700, median ~€1,400. Most analysts assign higher growth/margin assumptions than our conservative base case, justifying higher valuations. Model underpins a bear/base case floor valuation. Source: TradingView analyst estimates, Mar-2026
A29: NOTE: Negative alpha means the market price EXCEEDS our model intrinsic value - the stock is NOT a BUY on pure model grounds. The market assigns a significant premium for: (1) High-NA EUV option value, (2) AI-era demand visibility, (3) monopoly durability. Key exam point: CAPM tells us the REQUIRED return; comparing to implied return gives alpha. Negative alpha = price is too high relative to intrinsic value under our assumptions. Beta 1.35 (WFE cyclicality). Rf 2.8% (Bund Mar-2026). ERP 5.5% (Damodaran 2026, damodaran.com).

Sheet 6. SUMMARY
A1: ASML HOLDING N.V. | VALUATION SUMMARY — REPORT-READY OUTPUT
A2: March 2026 | Updated with FY2025 & Mar-2026 Market Data
A4: A. ANALYST RECOMMENDATION
A5: Rating | B5: HOLD
A6: 12-Month Price Target (€) | B6: ='1. INPUTS'!B38 -> 577.68137
A7: Current Share Price (€) | B7: ='1. INPUTS'!B6 -> 1150
A8: Upside Potential (%) | B8: =(B6-B7)/B7 -> -0.49766838
A9: Sector | B9: Semiconductors / WFE
A10: Exchange | B10: Euronext Amsterdam / NASDAQ
A12: B. VALUATION OUTPUT SUMMARY (Cross-referenced to Model)
A13: Valuation Method | B13: Output Value (€) | C13: Notes | D13: Sheet Reference
A14: DCF Intrinsic Value | B14: ='3. DCF VALUATION'!B35 -> 550.95822 | C14: FCFF DCF, WACC 9.0%, TGR 3.0% | D14: 3. DCF VALUATION
A15: P/E Implied Price | B15: ='4. COMP VALUATION'!H18 -> 586.8625 | C15: Peer avg P/E applied to NTM EPS | D15: 4. COMP VALUATION
A16: EV/EBITDA Implied Price | B16: ='4. COMP VALUATION'!H19 -> 621.94652 | C16: Peer avg EV/EBITDA × NTM EBITDA | D16: 4. COMP VALUATION
A17: Average (Comps) | B17: ='4. COMP VALUATION'!H21 -> 604.40451 | C17: Average of comp methods | D17: 4. COMP VALUATION
A18: Current Share Price | B18: ='1. INPUTS'!B6 -> 1150 | C18: Euronext, March 2026 | D18: 1. INPUTS
A20: C. CAPM OUTPUT SUMMARY
A21: Parameter | B21: Value | C21: Formula | D21: Interpretation
A22: Risk-Free Rate (Rf) | B22: ='5. CAPM'!B6 -> 0.028 | C22: Given | D22: 10Y German Bund, Mar-2026
A23: Beta (β) | B23: ='5. CAPM'!B7 -> 1.35 | C23: 5Y monthly regression | D23: Reflects WFE sector cyclicality
A24: ERP | B24: ='5. CAPM'!B8 -> 0.055 | C24: Damodaran 2025 | D24: Western Europe implied ERP
A25: Required Return E(Ri) | B25: ='5. CAPM'!B12 -> 0.10225 | C25: Rf + β×ERP | D25: Min return to hold ASML
A26: Implied Total Return | B26: ='5. CAPM'!B19 -> -0.20851934 | C26: (TV/P₀–1) + Div Yield | D26: IRR from DCF + dividend
A27: Alpha Signal | B27: ='5. CAPM'!B21 -> -0.31076934 | C27: Implied - Required | D27: Negative → stock ABOVE model intrinsic value → Hold recommendation reflects strong business fundamentals offset by valuation premium relative to intrinsic value estimates.
A29: D. KEY FINANCIAL METRICS (For Report Tables)
A30: Metric | B30: FY2024A | C30: FY2025E | D30: FY2026E
A31: Revenue (€m) | B31: ='2. HISTORICAL'!E6 -> 28261 | C31: ='2. HISTORICAL'!F6 -> 32667 | D31: ='3. DCF VALUATION'!C6 -> 36587.04
A32: EBIT (€m) | B32: ='2. HISTORICAL'!E10 -> 9023 | C32: ='2. HISTORICAL'!F10 -> 11301 | D32: ='3. DCF VALUATION'!C11 -> 12073.723
A33: Net Income (€m) | B33: ='2. HISTORICAL'!E12 -> 7572 | C33: ='2. HISTORICAL'!F12 -> 9609 | D33: ='3. DCF VALUATION'!C11*(1-'1. INPUTS'!B30) -> 10323.033
A34: EBIT Margin | B34: ='2. HISTORICAL'!E11 -> 0.31927391 | C34: ='2. HISTORICAL'!F11 -> 0.34594545 | D34: ='3. DCF VALUATION'!C10 -> 0.33
A35: EPS (€, diluted) | B35: ='2. HISTORICAL'!E14 -> 19.24 | C35: ='2. HISTORICAL'!F14 -> 24.71 | D35: =D33/'1. INPUTS'!B7 -> 26.95309
A36: P/E (×) | B36: ='2. HISTORICAL'!E27 -> 34.3x | C36: ='2. HISTORICAL'!F27 -> 29.8x | D36: ='1. INPUTS'!B6/D35 -> 42.666723
A59: Updated (Mar-2026): Alpha is NEGATIVE (-23% approx). This means the implied return from DCF convergence UNDERPERFORMS the CAPM required return. Interpretation: HOLD — the stock offers less than required return at current price based on our model. The market disagrees, pricing in optionality beyond base-case. Key viva point: negative alpha ≠ sell if growth assumptions are conservative.

Sheet CHARTS
A1: ASML — EMBEDDED CHARTS | March 2026
A3: Year | B3: Net Income (€m) | C3: Revenue (€m) | D3: EBIT Margin | E3: Net Margin | G3: Company | H3: P/E (×) | I3: EV/EBITDA (×)
A4: FY2021 | B4: ='2. HISTORICAL'!B12 -> 5882 | C4: ='2. HISTORICAL'!B6 -> 18611 | D4: ='2. HISTORICAL'!B11 -> 0.30793617 | E4: ='2. HISTORICAL'!B13 -> 0.31604965 | G4: ASML | H4: 40 | I4: 31
A5: FY2022 | B5: ='2. HISTORICAL'!C12 -> 5624 | C5: ='2. HISTORICAL'!C6 -> 21173 | D5: ='2. HISTORICAL'!C11 -> 0.28111274 | E5: ='2. HISTORICAL'!C13 -> 0.26562131 | G5: Applied Materials | H5: 20 | I5: 15
A6: FY2023 | B6: ='2. HISTORICAL'!D12 -> 7837 | C6: ='2. HISTORICAL'!D6 -> 27559 | D6: ='2. HISTORICAL'!D11 -> 0.32711637 | E6: ='2. HISTORICAL'!D13 -> 0.28437171 | G6: Lam Research | H6: 22 | I6: 16
A7: FY2024 | B7: ='2. HISTORICAL'!E12 -> 7572 | C7: ='2. HISTORICAL'!E6 -> 28261 | D7: ='2. HISTORICAL'!E11 -> 0.31927391 | E7: ='2. HISTORICAL'!E13 -> 0.26793107 | G7: KLA Corporation | H7: 25 | I7: 18
A8: FY2025E | B8: ='2. HISTORICAL'!F12 -> 9609 | C8: ='2. HISTORICAL'!F6 -> 32667 | D8: ='2. HISTORICAL'!F11 -> 0.34594545 | E8: ='2. HISTORICAL'!F13 -> 0.29415006 | G8: Tokyo Electron | H8: 28 | I8: 20
A9: FY2026E | B9: ='3. DCF VALUATION'!C13 -> 10323.033 | C9: ='3. DCF VALUATION'!C6 -> 36587.04 | D9: ='3. DCF VALUATION'!C10 -> 0.33 | E9: =B9/C9 -> 0.28215
A10: FY2027E | B10: ='3. DCF VALUATION'!D13 -> 11355.337 | C10: ='3. DCF VALUATION'!D6 -> 40245.744 | D10: ='3. DCF VALUATION'!D10 -> 0.33 | E10: =B10/C10 -> 0.28215
A11: FY2028E | B11: ='3. DCF VALUATION'!E13 -> 12635.393 | C11: ='3. DCF VALUATION'!E6 -> 43465.404 | D11: ='3. DCF VALUATION'!E10 -> 0.34 | E11: =B11/C11 -> 0.2907
A12: FY2029E | B12: ='3. DCF VALUATION'!F13 -> 13393.516 | C12: ='3. DCF VALUATION'!F6 -> 46073.328 | D12: ='3. DCF VALUATION'!F10 -> 0.34 | E12: =B12/C12 -> 0.2907
A13: FY2030E | B13: ='3. DCF VALUATION'!G13 -> 14476.815 | C13: ='3. DCF VALUATION'!G6 -> 48376.994 | D13: ='3. DCF VALUATION'!G10 -> 0.35 | E13: =B13/C13 -> 0.29925
